# Debugging Log

This document tracks all debugging activities for the aicvgen project.

## Bug Entry: BUG-aicvgen-001

**Bug ID/Reference:** BUG-aicvgen-001  
**Reported By & Date:** User, 2024-01-20  
**Severity/Priority:** High  
**Status:** Verified & Closed  

**Initial [BUG_REPORT] Summary:**
Errors are not being logged to `c:\Users\Nitro\Desktop\aicvgen\logs\error\error.log` anymore. The error log file appears to be empty despite the application having multiple error logging calls throughout the codebase.

**Environment Details:**
- OS: Windows
- Project: aicvgen (AI CV Generator)
- Logging Framework: Python logging with custom configuration
- Log Directory: `c:\Users\Nitro\Desktop\aicvgen\logs`

---

**Debugging Journal:**

**Date/Timestamp:** 2024-01-20  
**Hypothesis:** The error log file exists but is empty, suggesting either logging is not configured properly or the error directory structure is missing.  
**Action/Tool Used:** Examined the error log file content using view_files tool  
**Code Snippet Under Review:** `c:\Users\Nitro\Desktop\aicvgen\logs\error\error.log`  
**Observations/Results:** The error log file is completely empty (0 bytes), confirming that no errors are being logged to this file.  
**Next Steps:** Check the logging configuration to understand how error logging is set up.

**Date/Timestamp:** 2024-01-20  
**Hypothesis:** The logging configuration might have issues with error handler setup or directory creation.  
**Action/Tool Used:** Examined logging configuration in `src/config/logging_config.py`  
**Code Snippet Under Review:**
```python
# Error log (for ERROR and CRITICAL only)
error_handler = logging.handlers.RotatingFileHandler(
    logs_dir / "error" / "error.log",
    maxBytes=5*1024*1024,  # 5MB
    backupCount=3
)
error_handler.setLevel(logging.ERROR)
error_handler.setFormatter(detailed_formatter)
error_handler.addFilter(sensitive_filter)  # Add sensitive data filter
root_logger.addHandler(error_handler)
```
**Observations/Results:** The logging configuration correctly sets up an error handler that should log ERROR and CRITICAL level messages to `logs/error/error.log`. The configuration looks correct.  
**Next Steps:** Check if the error directory structure exists.

**Date/Timestamp:** 2024-01-20  
**Hypothesis:** The error directory might not exist, causing the RotatingFileHandler to fail silently.  
**Action/Tool Used:** Listed the contents of the logs directory using list_dir tool  
**Observations/Results:** Found that the logs directory structure is:
```
logs/
├── .gitkeep
├── README.md
├── llm/
└── rate_limit/
```
The `error/` directory is **missing** from the logs folder!  
**Next Steps:** Create the missing error directory and verify the logging configuration creates subdirectories.

**Date/Timestamp:** 2024-01-20  
**Hypothesis:** The logging setup function should create the error directory, but it might not be working properly or the directory was accidentally deleted.  
**Action/Tool Used:** Examined the directory creation code in `setup_logging()` function  
**Code Snippet Under Review:**
```python
# Create subdirectories for different log types
(logs_dir / "debug").mkdir(exist_ok=True)
(logs_dir / "error").mkdir(exist_ok=True)
(logs_dir / "access").mkdir(exist_ok=True)
(logs_dir / "llm").mkdir(exist_ok=True)
(logs_dir / "rate_limit").mkdir(exist_ok=True)
```
**Observations/Results:** The setup_logging() function does include code to create the error directory. However, the directory is missing, suggesting either:
1. The setup_logging() function is not being called properly
2. The directory was created but later deleted
3. There's a permissions issue preventing directory creation  
**Next Steps:** Create the missing error directory and error.log file manually to restore error logging functionality.

---

**Root Cause Analysis:**
The root cause of the error logging issue is that the `logs/error/` directory is missing from the file system. While the logging configuration in `src/config/logging_config.py` correctly sets up an error handler to write to `logs/error/error.log`, and the `setup_logging()` function includes code to create the error directory, the directory does not exist in the current file system.

This could have occurred due to:
1. The directory being accidentally deleted
2. The setup_logging() function not being called during application initialization
3. A permissions issue preventing directory creation
4. The directory creation code failing silently

The RotatingFileHandler fails silently when the target directory doesn't exist, which explains why no errors were being logged.

**Solution Implemented:**

**Description of the fix strategy:**
Manually create the missing `logs/error/` directory and `error.log` file to restore error logging functionality immediately. This addresses the immediate issue while the underlying directory creation logic can be investigated separately.

**Affected Files/Modules:**
- `logs/error/error.log` (created)
- `DEBUGGING_LOG.md` (created/updated)

**Code Changes (Diff or Snippet):**
```diff
+ Created directory: logs/error/
+ Created file: logs/error/error.log (empty file to initialize logging)
```

**Verification Steps:**
1. Confirmed the `logs/error/` directory now exists
2. Confirmed the `logs/error/error.log` file exists and is ready to receive log entries
3. Created and ran test script `test_error_logging.py` to verify error logging functionality
4. **VERIFIED**: Error and critical messages are now being properly logged to `logs/error/error.log`
5. Test results showed:
   - Error log file contains logged messages
   - Both ERROR and CRITICAL level messages are captured
   - Log format is correct with timestamp, logger name, level, file location, and message
   - Example log entry: `2025-06-20 01:12:18,989 - root - CRITICAL - test_error_logging.py:22 - TEST CRITICAL: This is a test critical message`

**Potential Side Effects/Risks Considered:**
- No negative side effects expected from creating the missing directory and file
- This fix restores the intended logging behavior
- May want to investigate why the directory creation in setup_logging() didn't work originally

**Resolution Date:** 2024-01-20

---

## Bug Entry #2

**Bug ID/Reference:** BUG-aicvgen-002  
**Reported By & Date:** User, 2024-12-19  
**Severity/Priority:** High  
**Status:** Verified & Closed  
**Initial `[BUG_REPORT]` Summary:** Application error showing "'AppConfig' object has no attribute 'vector_store_path'" when trying to access the vector store service.  
**Environment Details:** Windows, Python, Streamlit application

---

**Debugging Journal:**

**Date/Timestamp:** 2024-12-19  
**Hypothesis:** There's a mismatch between the attribute name used in VectorStoreService and the actual configuration structure in AppConfig.  
**Action/Tool Used:** Searched for "vector_store_path" and "AppConfig" in the codebase to identify the discrepancy.  
**Code Snippet Under Review:**
```python
# In vector_store_service.py
client = chromadb.PersistentClient(path=self.settings.vector_store_path)

# In settings.py - VectorDBConfig
class VectorDBConfig:
    persist_directory: str = "data/vector_db"
```
**Observations/Results:** Found that VectorStoreService was trying to access `self.settings.vector_store_path` but the AppConfig class has a `vector_db` sub-configuration with `persist_directory` attribute instead.  
**Next Steps:** Update VectorStoreService to use the correct attribute path.

---

**Root Cause Analysis:** The VectorStoreService was using an outdated attribute name `vector_store_path` that doesn't exist in the current AppConfig structure. The correct path should be `self.settings.vector_db.persist_directory` to access the ChromaDB persistence directory.

**Solution Implemented:**
Description of the fix strategy: Updated all references in VectorStoreService to use the correct configuration attribute path.

**Affected Files/Modules:**
- `src/services/vector_store_service.py`
- `tests/unit/test_vector_store_service.py`

**Code Changes (Diff):**
```python
# Before:
client = chromadb.PersistentClient(path=self.settings.vector_store_path)
logger.info(f"Successfully connected to ChromaDB at {self.settings.vector_store_path}")

# After:
client = chromadb.PersistentClient(path=self.settings.vector_db.persist_directory)
logger.info(f"Successfully connected to ChromaDB at {self.settings.vector_db.persist_directory}")
```

**Verification Steps:**
- Fixed the attribute access in VectorStoreService `_connect()` method
- Updated corresponding test mocks to use the correct structure
- Error should no longer appear when accessing vector store functionality

**Potential Side Effects/Risks Considered:** Low risk change as it's correcting a configuration access pattern. All vector store operations should now work correctly.

**Resolution Date:** 2024-12-19